Workbook

Sheet A.1 Fed & State by Category
A1: A.1.: Federal TANF and State MOE Expenditures Summary by ACF-196R Spending Category, FY 2024
A2: Spending Category | B2: Federal Funds | C2: State MOE in TANF and Separate State Programs | D2: All Funds | E2: Percent of Total Funds Used
A3: Basic Assistance | B3: ='C.1 Federal Expenditures'!$G$3 -> 3.1621428e+09 | C3: ='C.2 State Expenditures'!$G$3 -> 5.0238706e+09 | D3: ='B. Total Expenditures'!$G$3 -> 8.1860134e+09 | E3: =D3/($D$44) -> 0.21820227
A4: Basic Assistance (excluding Relative Foster Care Maintenance Payments and Adoption and Guardianship Subsidies) | B4: ='C.1 Federal Expenditures'!$H$3 -> 2.9743012e+09 | C4: ='C.2 State Expenditures'!$H$3 -> 4.8140162e+09 | D4: ='B. Total Expenditures'!$H$3 -> 7.7883175e+09 | E4: =D4/($D$44) -> 0.20760148
A5: Relative Foster Care Maintenance Payments and Adoption and Guardianship Subsidies | B5: ='C.1 Federal Expenditures'!$I$3 -> 1.8784159e+08 | C5: ='C.2 State Expenditures'!$I$3 -> 2.0985435e+08 | D5: ='B. Total Expenditures'!$I$3 -> 3.9769595e+08 | E5: =D5/($D$44) -> 0.010600784
A6: Assistance Authorized Solely Under Prior Law | B6: ='C.1 Federal Expenditures'!$J$3 -> 6.6569711e+08 | D6: ='B. Total Expenditures'!$J$3 -> 6.6569711e+08 | E6: =D6/($D$44) -> 0.017744488
A7: Foster Care Payments | B7: ='C.1 Federal Expenditures'!$K$3 -> 3.2630592e+08 | D7: ='B. Total Expenditures'!$K$3 -> 3.2630592e+08 | E7: =D7/($D$44) -> 0.0086978467
A8: Juvenile Justice Payments | B8: ='C.1 Federal Expenditures'!$L$3 -> 16012900 | D8: ='B. Total Expenditures'!$L$3 -> 16012900 | E8: =D8/($D$44) -> 0.00042683184
A9: Emergency Assistance Authorized Solely Under Prior Law | B9: ='C.1 Federal Expenditures'!$M$3 -> 3.2337829e+08 | D9: ='B. Total Expenditures'!$M$3 -> 3.2337829e+08 | E9: =D9/($D$44) -> 0.0086198095
A10: Non-Assistance Authorized Solely Under Prior Law | B10: ='C.1 Federal Expenditures'!$N$3 -> 6.2277337e+08 | D10: ='B. Total Expenditures'!$N$3 -> 6.2277337e+08 | E10: =D10/($D$44) -> 0.016600334
A11: Child Welfare or Foster Care Services | B11: ='C.1 Federal Expenditures'!$O$3 -> 5.3262456e+08 | D11: ='B. Total Expenditures'!$O$3 -> 5.3262456e+08 | E11: =D11/($D$44) -> 0.014197373
A12: Juvenile Justice Services | B12: ='C.1 Federal Expenditures'!$P$3 -> 2938023 | D12: ='B. Total Expenditures'!$P$3 -> 2938023 | E12: =D12/($D$44) -> 7.8314467e-05
A13: Emergency Services Authorized Solely Under Prior Law | B13: ='C.1 Federal Expenditures'!$Q$3 -> 87210783 | D13: ='B. Total Expenditures'!$Q$3 -> 87210783 | E13: =D13/($D$44) -> 0.0023246469
A14: Work, Education, and Training Activities | B14: ='C.1 Federal Expenditures'!$R$3 -> 2.2306071e+09 | C14: ='C.2 State Expenditures'!$R$3 -> 6.6529529e+08 | D14: ='B. Total Expenditures'!$R$3 -> 2.8959024e+09 | E14: =D14/($D$44) -> 0.077191722
A15: Subsidized Employment | B15: ='C.1 Federal Expenditures'!$S$3 -> 1.2363827e+08 | C15: ='C.2 State Expenditures'!$S$3 -> 18209880 | D15: ='B. Total Expenditures'!$S$3 -> 1.4184815e+08 | E15: =D15/($D$44) -> 0.0037810332
A16: Education and Training | B16: ='C.1 Federal Expenditures'!$T$3 -> 7.7172189e+08 | C16: ='C.2 State Expenditures'!$T$3 -> 4.7852835e+08 | D16: ='B. Total Expenditures'!$T$3 -> 1.2502502e+09 | E16: =D16/($D$44) -> 0.033326043
A17: Additional Work Activities | B17: ='C.1 Federal Expenditures'!$U$3 -> 1.335247e+09 | C17: ='C.2 State Expenditures'!$U$3 -> 1.6855706e+08 | D17: ='B. Total Expenditures'!$U$3 -> 1.503804e+09 | E17: =D17/($D$44) -> 0.040084646
A18: Work Supports | B18: ='C.1 Federal Expenditures'!$V$3 -> 4.0950004e+08 | C18: ='C.2 State Expenditures'!$V$3 -> 69829002 | D18: ='B. Total Expenditures'!$V$3 -> 4.7932905e+08 | E18: =D18/($D$44) -> 0.012776755
A19: Early Care and Education | B19: ='C.1 Federal Expenditures'!$W$3 -> 1.5785933e+09 | C19: ='C.2 State Expenditures'!$W$3 -> 6.8940141e+09 | D19: ='B. Total Expenditures'!$W$3 -> 8.4726074e+09 | E19: =D19/($D$44) -> 0.22584157
A20: Child Care (Assistance and Non-Assistance) | B20: ='C.1 Federal Expenditures'!$X$3 -> 1.5348473e+09 | C20: ='C.2 State Expenditures'!$X$3 -> 3.4708756e+09 | D20: ='B. Total Expenditures'!$X$3 -> 5.005723e+09 | E20: =D20/($D$44) -> 0.13343004
A21: Pre-Kindergarten/Head Start | B21: ='C.1 Federal Expenditures'!$Y$3 -> 43745919 | C21: ='C.2 State Expenditures'!$Y$3 -> 3423138498 | D21: ='B. Total Expenditures'!$Y$3 -> 3.4668844e+09 | E21: =D21/($D$44) -> 0.092411531
A22: Financial Education and Asset Development | B22: ='C.1 Federal Expenditures'!$Z$3 -> 5238564.3 | C22: ='C.2 State Expenditures'!$Z$3 -> 773135.02 | D22: ='B. Total Expenditures'!$Z$3 -> 6011699.3 | E22: =D22/($D$44) -> 0.00016024484
A23: Refundable Earned Income Tax Credits | B23: ='C.1 Federal Expenditures'!$AA$3 -> 340949067 | C23: ='C.2 State Expenditures'!$AA$3 -> 3.0284958e+09 | D23: ='B. Total Expenditures'!$AA$3 -> 3.3694449e+09 | E23: =D23/($D$44) -> 0.089814233
A24: Non-EITC Refundable State Tax Credits | B24: ='C.1 Federal Expenditures'!$AB$3 -> 0 | C24: ='C.2 State Expenditures'!$AB$3 -> 7.0071808e+08 | D24: ='B. Total Expenditures'!$AB$3 -> 7.0071808e+08 | E24: =D24/($D$44) -> 0.018677989
A25: Non-Recurrent Short Term Benefits | B25: ='C.1 Federal Expenditures'!$AC$3 -> 4.9742062e+08 | C25: ='C.2 State Expenditures'!$AC$3 -> 7.2164444e+08 | D25: ='B. Total Expenditures'!$AC$3 -> 1.2190651e+09 | E25: =D25/($D$44) -> 0.032494787
A26: Supportive Services | B26: ='C.1 Federal Expenditures'!$AD$3 -> 2.027766e+08 | C26: ='C.2 State Expenditures'!$AD$3 -> 2.7268818e+08 | D26: ='B. Total Expenditures'!$AD$3 -> 4.7546479e+08 | E26: =D26/($D$44) -> 0.012673751
A27: Services for Children and Youth | B27: ='C.1 Federal Expenditures'!$AE$3 -> 3.012908e+08 | C27: ='C.2 State Expenditures'!$AE$3 -> 9.6059804e+08 | D27: ='B. Total Expenditures'!$AE$3 -> 1.2618888e+09 | E27: =D27/($D$44) -> 0.033636276
A28: Prevention of Out-of-Wedlock Pregnancies | B28: ='C.1 Federal Expenditures'!$AF$3 -> 1.3612964e+08 | C28: ='C.2 State Expenditures'!$AF$3 -> 1.5870698e+08 | D28: ='B. Total Expenditures'!$AF$3 -> 2.9483662e+08 | E28: =D28/($D$44) -> 0.0078590169
A29: Fatherhood and Two-Parent Family Formation and Maintenance Programs | B29: ='C.1 Federal Expenditures'!$AG$3 -> 1.3989021e+08 | C29: ='C.2 State Expenditures'!$AG$3 -> 51944708 | D29: ='B. Total Expenditures'!$AG$3 -> 1.9183492e+08 | E29: =D29/($D$44) -> 0.0051134554
A30: Child Welfare Services | B30: ='C.1 Federal Expenditures'!$AH$3 -> 1.4339291e+09 | C30: ='C.2 State Expenditures'!$AH$3 -> 7.2911207e+08 | D30: ='B. Total Expenditures'!$AH$3 -> 2.1630412e+09 | E30: =D30/($D$44) -> 0.057656941
A31: Family Support/Family Preservation /Reunification Services | B31: ='C.1 Federal Expenditures'!$AI$3 -> 7.5380388e+08 | C31: ='C.2 State Expenditures'!$AI$3 -> 2.92122e+08 | D31: ='B. Total Expenditures'!$AI$3 -> 1.0459259e+09 | E31: =D31/($D$44) -> 0.027879675
A32: Adoption Services | B32: ='C.1 Federal Expenditures'!$AJ$3 -> 9341253.8 | C32: ='C.2 State Expenditures'!$AJ$3 -> 14146890 | D32: ='B. Total Expenditures'!$AJ$3 -> 23488144 | E32: =D32/($D$44) -> 0.00062608818
A33: Additional Child Welfare Services | B33: ='C.1 Federal Expenditures'!$AK$3 -> 6.70784e+08 | C33: ='C.2 State Expenditures'!$AK$3 -> 4.2284317e+08 | D33: ='B. Total Expenditures'!$AK$3 -> 1.0936272e+09 | E33: =D33/($D$44) -> 0.029151177
A34: Home Visiting Programs | B34: ='C.1 Federal Expenditures'!$AL$3 -> 1.5634873e+08 | C34: ='C.2 State Expenditures'!$AL$3 -> 19671743 | D34: ='B. Total Expenditures'!$AL$3 -> 1.7602047e+08 | E34: =D34/($D$44) -> 0.0046919134
A35: Program Management | B35: ='C.1 Federal Expenditures'!$AM$3 -> 2.5248775e+09 | C35: ='C.2 State Expenditures'!$AM$3 -> 1.1605311e+09 | D35: ='B. Total Expenditures'!$AM$3 -> 3.6854086e+09 | E35: =D35/($D$44) -> 0.098236402
A36: Administrative Costs | B36: ='C.1 Federal Expenditures'!$AN$3 -> 1.4188003e+09 | C36: ='C.2 State Expenditures'!$AN$3 -> 9.4290159e+08 | D36: ='B. Total Expenditures'!$AN$3 -> 2.3617018e+09 | E36: =D36/($D$44) -> 0.062952339
A37: Assessment/Service Provision | B37: ='C.1 Federal Expenditures'!$AO$3 -> 9.044844e+08 | C37: ='C.2 State Expenditures'!$AO$3 -> 1.4810933e+08 | D37: ='B. Total Expenditures'!$AO$3 -> 1.0525937e+09 | E37: =D37/($D$44) -> 0.02805741
A38: Systems | B38: ='C.1 Federal Expenditures'!$AP$3 -> 2.0159279e+08 | C38: ='C.2 State Expenditures'!$AP$3 -> 69520210 | D38: ='B. Total Expenditures'!$AP$3 -> 2.71113e+08 | E38: =D38/($D$44) -> 0.0072266522
A39: Other | B39: ='C.1 Federal Expenditures'!$AQ$3 -> 23894834 | C39: ='C.2 State Expenditures'!$AQ$3 -> 1.1039693e+08 | D39: ='B. Total Expenditures'!$AQ$3 -> 1.3429176e+08 | E39: =D39/($D$44) -> 0.0035796138
A40: TOTAL EXPENDITURES | B40: ='C.1 Federal Expenditures'!$AR$3 -> 1.4432059e+10 | C40: ='C.2 State Expenditures'!$AR$3 -> 2.056829e+10 | D40: ='B. Total Expenditures'!$AR$3 -> 3.500035e+10 | E40: =D40/($D$44) -> 0.93295176
...

Sheet A.5 FY24 Federal TANF Funds
A1: A.5.: Breakdown of Total Federal TANF Funds Available in FY 2024
A2: FY 2024 Federal TANF Funds
A3: State Family Assistance Grant | B3: ='E.2 SFAG'!B3 -> 1.6212099e+10
A4: Contingency Funds | B4: ='E.5 Contingency'!B3 -> 608000000
A5: Total FY 2024 Federal Awards | B5: =SUM(B3:B4) -> 1.6820099e+10
A6: Carryover from Prior Years
A7: State Family Assistance Grant | B7: ='E.2 SFAG'!F3 -> 9.7834044e+09
A8: Total Funds Available | B8: =B5+B7 -> 2.6603503e+10

Sheet B. Total Expenditures
B1: B.: Total Federal TANF and State MOE Expenditures in FY 2024
A2: STATE | B2: 1. Awarded | C2: 2. Transferred to CCDF Discretionary | D2: 3. Transfered to SSBG | E2: 4. Adjusted Award | F2: 5. Carryover | G2: 6. Basic Assistance | H2: 6.a. Basic Assistance - (excluding Relative Foster Care Maintenance Payments and Adoption and Guardianship Subsidies) | I2: 6.b. Basic Assistance - Relative Foster Care Maintenance Payments and Adoption and Guardianship Subsidies | J2: 7. Assistance Authorized Solely Under Prior Law | K2: 7.a. Assistance Authorized Solely Under Prior Law - Foster Care Payments | L2: 7.b. Assistance Authorized Solely Under Prior Law- Juvenile Justice Payments | M2: 7.c. Assistance Authorized Solely Under Prior Law - Emergency Assistance | N2: 8. Non-Assistance Authorized Solely Under Prior Law | O2: 8.a. Non-Assistance Authorized Solely Under Prior Law - Child Welfare or Foster Care Services | P2: 8.b. Non-Assistance Authorized Solely Under Prior Law - Juvenile Justice Services | Q2: 8.c. Non-Assistance Authorized Solely Under Prior Law - Emergency Services | R2: 9. Work, Education, and Training Activities | S2: 9.a. Work, Education, and Training Activities - Subsidized Employment | T2: 9.b. Work, Education, and Training Activities - Education and Training | U2: 9.c. Work, Education, and Training Activities - Additional Work Activities | V2: 10. Work Supports | W2: 11. Early Care and Education | X2: 11.a. Early Care and Education - Child Care (Assistance and Non-Assistance) | Y2: 11.b. Early Care and Education - Pre-Kindergarten/Head Start | Z2: 12. Financial Education and Asset Development | AA2: 13. Refundable Earned Income Tax Credits | AB2: 14. Non-EITC Refundable State Tax Credits | AC2: 15. Non-Recurrent Short Term Benefits | AD2: 16. Supportive Services | AE2: 17. Services for Children and Youth | AF2: 18. Prevention of Out-of-Wedlock Pregnancies | AG2: 19. Fatherhood and Two-Parent Family Formation and Maintenance Programs | AH2: 20. Child Welfare Services | AI2: 20.a. Child Welfare Services - Family Support/Family Preservation /Reunification Services | AJ2: 20.b. Child Welfare Services - Adoption Services | AK2: 20.c. Child Welfare Services - Additional Child Welfare Services | AL2: 21. Home Visiting Programs | AM2: 22. Program Management | AN2: 22.a. Program Management - Administrative Costs | AO2: 22.b. Program Management - Assessment/Service Provision | AP2: 22.c. Program Management - Systems | AQ2: 23. Other | AR2: 24. Total Expenditures | AS2: 27. Federal Unliquidated Obligations | AT2: 28. Unobligated Balance
A3: U.S. TOTAL | B3: ='C.1 Federal Expenditures'!B3+'C.2 State Expenditures'!B3 -> 1.6820099e+10 | C3: ='C.1 Federal Expenditures'!C3+'C.2 State Expenditures'!C3 -> 1.387091e+09 | D3: ='C.1 Federal Expenditures'!D3+'C.2 State Expenditures'!D3 -> 1.1282716e+09 | E3: ='C.1 Federal Expenditures'!E3+'C.2 State Expenditures'!E3 -> 1.3696736e+10 | F3: ='C.1 Federal Expenditures'!F3+'C.2 State Expenditures'!F3 -> 9.7834044e+09 | G3: ='C.1 Federal Expenditures'!G3+'C.2 State Expenditures'!G3 -> 8.1860134e+09 | H3: ='C.1 Federal Expenditures'!H3+'C.2 State Expenditures'!H3 -> 7.7883175e+09 | I3: ='C.1 Federal Expenditures'!I3+'C.2 State Expenditures'!I3 -> 3.9769595e+08 | ... AR3: ='C.1 Federal Expenditures'!AR3+'C.2 State Expenditures'!AR3 -> 3.500035e+10 | AS3: ='C.1 Federal Expenditures'!AS3 -> 1.6696103e+09 | AT3: ='C.1 Federal Expenditures'!AT3 -> 7.9864706e+09
A4: ALABAMA | B4: ='C.1 Federal Expenditures'!B4+'C.2 State Expenditures'!B4 -> 1.0360879e+08 | C4: ='C.1 Federal Expenditures'!C4+'C.2 State Expenditures'!C4 -> 18601451 | D4: ='C.1 Federal Expenditures'!D4+'C.2 State Expenditures'!D4 -> 9300725 | E4: ='C.1 Federal Expenditures'!E4+'C.2 State Expenditures'!E4 -> 65105091 | F4: ='C.1 Federal Expenditures'!F4+'C.2 State Expenditures'!F4 -> 59234364 | G4: ='C.1 Federal Expenditures'!G4+'C.2 State Expenditures'!G4 -> 32124953 | H4: ='C.1 Federal Expenditures'!H4+'C.2 State Expenditures'!H4 -> 32124953 | I4: ='C.1 Federal Expenditures'!I4+'C.2 State Expenditures'!I4 -> 0 | ... AR4: ='C.1 Federal Expenditures'!AR4+'C.2 State Expenditures'!AR4 -> 2.0587129e+08 | AS4: ='C.1 Federal Expenditures'!AS4 -> 0 | AT4: ='C.1 Federal Expenditures'!AT4 -> 46731540
A5: ALASKA | B5: ='C.1 Federal Expenditures'!B5+'C.2 State Expenditures'!B5 -> 32973844 | C5: ='C.1 Federal Expenditures'!C5+'C.2 State Expenditures'!C5 -> 6594768.7 | D5: ='C.1 Federal Expenditures'!D5+'C.2 State Expenditures'!D5 -> 3297384.4 | E5: ='C.1 Federal Expenditures'!E5+'C.2 State Expenditures'!E5 -> 23081690 | F5: ='C.1 Federal Expenditures'!F5+'C.2 State Expenditures'!F5 -> 15592121 | G5: ='C.1 Federal Expenditures'!G5+'C.2 State Expenditures'!G5 -> 18434756 | H5: ='C.1 Federal Expenditures'!H5+'C.2 State Expenditures'!H5 -> 18434756 | I5: ='C.1 Federal Expenditures'!I5+'C.2 State Expenditures'!I5 -> 0 | ... AR5: ='C.1 Federal Expenditures'!AR5+'C.2 State Expenditures'!AR5 -> 28721385 | AS5: ='C.1 Federal Expenditures'!AS5 -> 4754786.7 | AT5: ='C.1 Federal Expenditures'!AT5 -> 14477758
A6: ARIZONA | B6: ='C.1 Federal Expenditures'!B6+'C.2 State Expenditures'!B6 -> 2.2467641e+08 | C6: ='C.1 Federal Expenditures'!C6+'C.2 State Expenditures'!C6 -> 0 | D6: ='C.1 Federal Expenditures'!D6+'C.2 State Expenditures'!D6 -> 19940731 | E6: ='C.1 Federal Expenditures'!E6+'C.2 State Expenditures'!E6 -> 179466582 | F6: ='C.1 Federal Expenditures'!F6+'C.2 State Expenditures'!F6 -> 36485033 | G6: ='C.1 Federal Expenditures'!G6+'C.2 State Expenditures'!G6 -> 40017375 | H6: ='C.1 Federal Expenditures'!H6+'C.2 State Expenditures'!H6 -> 14421889 | I6: ='C.1 Federal Expenditures'!I6+'C.2 State Expenditures'!I6 -> 25595486 | ... AR6: ='C.1 Federal Expenditures'!AR6+'C.2 State Expenditures'!AR6 -> 3.4148939e+08 | AS6: ='C.1 Federal Expenditures'!AS6 -> 0 | AT6: ='C.1 Federal Expenditures'!AT6 -> 58358866
A7: ARKANSAS | B7: ='C.1 Federal Expenditures'!B7+'C.2 State Expenditures'!B7 -> 62991053 | C7: ='C.1 Federal Expenditures'!C7+'C.2 State Expenditures'!C7 -> 0 | D7: ='C.1 Federal Expenditures'!D7+'C.2 State Expenditures'!D7 -> 0 | E7: ='C.1 Federal Expenditures'!E7+'C.2 State Expenditures'!E7 -> 56545640 | F7: ='C.1 Federal Expenditures'!F7+'C.2 State Expenditures'!F7 -> 74209846 | G7: ='C.1 Federal Expenditures'!G7+'C.2 State Expenditures'!G7 -> 2434783.7 | H7: ='C.1 Federal Expenditures'!H7+'C.2 State Expenditures'!H7 -> 2434783.7 | I7: ='C.1 Federal Expenditures'!I7+'C.2 State Expenditures'!I7 -> 0 | ... AR7: ='C.1 Federal Expenditures'!AR7+'C.2 State Expenditures'!AR7 -> 1.3007365e+08 | AS7: ='C.1 Federal Expenditures'!AS7 -> 0 | AT7: ='C.1 Federal Expenditures'!AT7 -> 42384477
A8: CALIFORNIA | B8: ='C.1 Federal Expenditures'!B8+'C.2 State Expenditures'!B8 -> 3634115206 | C8: ='C.1 Federal Expenditures'!C8+'C.2 State Expenditures'!C8 -> 0 | D8: ='C.1 Federal Expenditures'!D8+'C.2 State Expenditures'!D8 -> 348723522 | E8: ='C.1 Federal Expenditures'!E8+'C.2 State Expenditures'!E8 -> 3285391684 | F8: ='C.1 Federal Expenditures'!F8+'C.2 State Expenditures'!F8 -> 3.8214189e+08 | G8: ='C.1 Federal Expenditures'!G8+'C.2 State Expenditures'!G8 -> 3.9084973e+09 | H8: ='C.1 Federal Expenditures'!H8+'C.2 State Expenditures'!H8 -> 3.7425402e+09 | I8: ='C.1 Federal Expenditures'!I8+'C.2 State Expenditures'!I8 -> 1.659571e+08 | ... AR8: ='C.1 Federal Expenditures'!AR8+'C.2 State Expenditures'!AR8 -> 8.0165506e+09 | AS8: ='C.1 Federal Expenditures'!AS8 -> 2.808688e+08 | AT8: ='C.1 Federal Expenditures'!AT8 -> 0
A9: COLORADO | B9: ='C.1 Federal Expenditures'!B9+'C.2 State Expenditures'!B9 -> 1.5106509e+08 | C9: ='C.1 Federal Expenditures'!C9+'C.2 State Expenditures'!C9 -> 896113.01 | D9: ='C.1 Federal Expenditures'!D9+'C.2 State Expenditures'!D9 -> 3066924.2 | E9: ='C.1 Federal Expenditures'!E9+'C.2 State Expenditures'!E9 -> 1.3164467e+08 | F9: ='C.1 Federal Expenditures'!F9+'C.2 State Expenditures'!F9 -> 1.0930136e+08 | G9: ='C.1 Federal Expenditures'!G9+'C.2 State Expenditures'!G9 -> 69699678 | H9: ='C.1 Federal Expenditures'!H9+'C.2 State Expenditures'!H9 -> 69699678 | I9: ='C.1 Federal Expenditures'!I9+'C.2 State Expenditures'!I9 -> 0 | ... AR9: ='C.1 Federal Expenditures'!AR9+'C.2 State Expenditures'!AR9 -> 5.5438683e+08 | AS9: ='C.1 Federal Expenditures'!AS9 -> 0 | AT9: ='C.1 Federal Expenditures'!AT9 -> 86106324
A10: CONNECTICUT | B10: ='C.1 Federal Expenditures'!B10+'C.2 State Expenditures'!B10 -> 265907706 | C10: ='C.1 Federal Expenditures'!C10+'C.2 State Expenditures'!C10 -> 26678810 | D10: ='C.1 Federal Expenditures'!D10+'C.2 State Expenditures'!D10 -> 0 | E10: ='C.1 Federal Expenditures'!E10+'C.2 State Expenditures'!E10 -> 239228896 | F10: ='C.1 Federal Expenditures'!F10+'C.2 State Expenditures'!F10 -> 0 | G10: ='C.1 Federal Expenditures'!G10+'C.2 State Expenditures'!G10 -> 42471685 | H10: ='C.1 Federal Expenditures'!H10+'C.2 State Expenditures'!H10 -> 42471685 | I10: ='C.1 Federal Expenditures'!I10+'C.2 State Expenditures'!I10 -> 0 | ... AR10: ='C.1 Federal Expenditures'!AR10+'C.2 State Expenditures'!AR10 -> 5.4063155e+08 | AS10: ='C.1 Federal Expenditures'!AS10 -> 0 | AT10: ='C.1 Federal Expenditures'!AT10 -> 0
A11: DELAWARE | B11: ='C.1 Federal Expenditures'!B11+'C.2 State Expenditures'!B11 -> 35852994 | C11: ='C.1 Federal Expenditures'!C11+'C.2 State Expenditures'!C11 -> 0 | D11: ='C.1 Federal Expenditures'!D11+'C.2 State Expenditures'!D11 -> 0 | E11: ='C.1 Federal Expenditures'!E11+'C.2 State Expenditures'!E11 -> 32184421 | F11: ='C.1 Federal Expenditures'!F11+'C.2 State Expenditures'!F11 -> 23079053 | G11: ='C.1 Federal Expenditures'!G11+'C.2 State Expenditures'!G11 -> 5754067.3 | H11: ='C.1 Federal Expenditures'!H11+'C.2 State Expenditures'!H11 -> 5754067.3 | I11: ='C.1 Federal Expenditures'!I11+'C.2 State Expenditures'!I11 -> 0 | ... AR11: ='C.1 Federal Expenditures'!AR11+'C.2 State Expenditures'!AR11 -> 84207746 | AS11: ='C.1 Federal Expenditures'!AS11 -> 35924999 | AT11: ='C.1 Federal Expenditures'!AT11 -> 0
A12: DIST.OF COLUMBIA | B12: ='C.1 Federal Expenditures'!B12+'C.2 State Expenditures'!B12 -> 1.0282559e+08 | C12: ='C.1 Federal Expenditures'!C12+'C.2 State Expenditures'!C12 -> 0 | D12: ='C.1 Federal Expenditures'!D12+'C.2 State Expenditures'!D12 -> 3922928.6 | E12: ='C.1 Federal Expenditures'!E12+'C.2 State Expenditures'!E12 -> 88381274 | F12: ='C.1 Federal Expenditures'!F12+'C.2 State Expenditures'!F12 -> 63679682 | G12: ='C.1 Federal Expenditures'!G12+'C.2 State Expenditures'!G12 -> 51920225 | H12: ='C.1 Federal Expenditures'!H12+'C.2 State Expenditures'!H12 -> 45666114 | I12: ='C.1 Federal Expenditures'!I12+'C.2 State Expenditures'!I12 -> 6254111.3 | ... AR12: ='C.1 Federal Expenditures'!AR12+'C.2 State Expenditures'!AR12 -> 3.6786669e+08 | AS12: ='C.1 Federal Expenditures'!AS12 -> 0 | AT12: ='C.1 Federal Expenditures'!AT12 -> 58694975
A13: FLORIDA | B13: ='C.1 Federal Expenditures'!B13+'C.2 State Expenditures'!B13 -> 560484398 | C13: ='C.1 Federal Expenditures'!C13+'C.2 State Expenditures'!C13 -> 110662022 | D13: ='C.1 Federal Expenditures'!D13+'C.2 State Expenditures'!D13 -> 56048440 | E13: ='C.1 Federal Expenditures'!E13+'C.2 State Expenditures'!E13 -> 3.9377394e+08 | F13: ='C.1 Federal Expenditures'!F13+'C.2 State Expenditures'!F13 -> 1.7179611e+08 | G13: ='C.1 Federal Expenditures'!G13+'C.2 State Expenditures'!G13 -> 1.4869961e+08 | H13: ='C.1 Federal Expenditures'!H13+'C.2 State Expenditures'!H13 -> 1.0034006e+08 | I13: ='C.1 Federal Expenditures'!I13+'C.2 State Expenditures'!I13 -> 48359547 | ... AR13: ='C.1 Federal Expenditures'!AR13+'C.2 State Expenditures'!AR13 -> 8.5390144e+08 | AS13: ='C.1 Federal Expenditures'!AS13 -> 0 | AT13: ='C.1 Federal Expenditures'!AT13 -> 2.0204558e+08
A14: GEORGIA | B14: ='C.1 Federal Expenditures'!B14+'C.2 State Expenditures'!B14 -> 329650291 | C14: ='C.1 Federal Expenditures'!C14+'C.2 State Expenditures'!C14 -> 0 | D14: ='C.1 Federal Expenditures'!D14+'C.2 State Expenditures'!D14 -> 2082791 | E14: ='C.1 Federal Expenditures'!E14+'C.2 State Expenditures'!E14 -> 327567500 | F14: ='C.1 Federal Expenditures'!F14+'C.2 State Expenditures'!F14 -> 241342196 | G14: ='C.1 Federal Expenditures'!G14+'C.2 State Expenditures'!G14 -> 71504290 | H14: ='C.1 Federal Expenditures'!H14+'C.2 State Expenditures'!H14 -> 10671069 | I14: ='C.1 Federal Expenditures'!I14+'C.2 State Expenditures'!I14 -> 60833221 | ... AR14: ='C.1 Federal Expenditures'!AR14+'C.2 State Expenditures'!AR14 -> 593991937 | AS14: ='C.1 Federal Expenditures'!AS14 -> 36243679 | AT14: ='C.1 Federal Expenditures'!AT14 -> 112042607
... A54: WYOMING | B54: ='C.1 Federal Expenditures'!B54+'C.2 State Expenditures'!B54 -> 18428651 | C54: ='C.1 Federal Expenditures'!C54+'C.2 State Expenditures'!C54 -> 0 | D54: ='C.1 Federal Expenditures'!D54+'C.2 State Expenditures'!D54 -> 0 | E54: ='C.1 Federal Expenditures'!E54+'C.2 State Expenditures'!E54 -> 18428651 | F54: ='C.1 Federal Expenditures'!F54+'C.2 State Expenditures'!F54 -> 23248932 | G54: ='C.1 Federal Expenditures'!G54+'C.2 State Expenditures'!G54 -> 13922297 | H54: ='C.1 Federal Expenditures'!H54+'C.2 State Expenditures'!H54 -> 5880765 | I54: ='C.1 Federal Expenditures'!I54+'C.2 State Expenditures'!I54 -> 8041532 | ... AR54: ='C.1 Federal Expenditures'!AR54+'C.2 State Expenditures'!AR54 -> 28964363 | AS54: ='C.1 Federal Expenditures'!AS54 -> 0 | AT54: ='C.1 Federal Expenditures'!AT54 -> 22375962

Sheet DC
A1: District of Columbia: Federal TANF and State MOE Expenditures Summary by ACF-196R Spending Category, FY 2024
A2: Spending Category | B2: Federal Funds | C2: State MOE in TANF and Separate State Programs | D2: All Funds | E2: Percent of Total Funds Used
A3: Basic Assistance | B3: ='C.1 Federal Expenditures'!$G$12 -> 39570809 | C3: ='C.2 State Expenditures'!$G$12 -> 12349415 | D3: ='B. Total Expenditures'!$G$12 -> 51920225 | E3: =D3/($D$44) -> 0.13964947
A4: Basic Assistance (excluding Relative Foster Care Maintenance Payments and Adoption and Guardianship Subsidies) | B4: ='C.1 Federal Expenditures'!$H$12 -> 39570809 | C4: ='C.2 State Expenditures'!$H$12 -> 6095304.2 | D4: ='B. Total Expenditures'!$H$12 -> 45666114 | E4: =D4/($D$44) -> 0.12282783
A5: Relative Foster Care Maintenance Payments and Adoption and Guardianship Subsidies | B5: ='C.1 Federal Expenditures'!$I$12 -> 0 | C5: ='C.2 State Expenditures'!$I$12 -> 6254111.3 | D5: ='B. Total Expenditures'!$I$12 -> 6254111.3 | E5: =D5/($D$44) -> 0.016821641
A6: Assistance Authorized Solely Under Prior Law | B6: ='C.1 Federal Expenditures'!$J$12 -> 0 | D6: ='B. Total Expenditures'!$J$12 -> 0 | E6: =D6/($D$44) -> 0
A7: Foster Care Payments | B7: ='C.1 Federal Expenditures'!$K$12 -> 0 | D7: ='B. Total Expenditures'!$K$12 -> 0 | E7: =D7/($D$44) -> 0
A8: Juvenile Justice Payments | B8: ='C.1 Federal Expenditures'!$L$12 -> 0 | D8: ='B. Total Expenditures'!$L$12 -> 0 | E8: =D8/($D$44) -> 0
A9: Emergency Assistance Authorized Solely Under Prior Law | B9: ='C.1 Federal Expenditures'!$M$12 -> 0 | D9: ='B. Total Expenditures'!$M$12 -> 0 | E9: =D9/($D$44) -> 0
A10: Non-Assistance Authorized Solely Under Prior Law | B10: ='C.1 Federal Expenditures'!$N$12 -> 0 | D10: ='B. Total Expenditures'!$N$12 -> 0 | E10: =D10/($D$44) -> 0
A11: Child Welfare or Foster Care Services | B11: ='C.1 Federal Expenditures'!$O$12 -> 0 | D11: ='B. Total Expenditures'!$O$12 -> 0 | E11: =D11/($D$44) -> 0
A12: Juvenile Justice Services | B12: ='C.1 Federal Expenditures'!$P$12 -> 0 | D12: ='B. Total Expenditures'!$P$12 -> 0 | E12: =D12/($D$44) -> 0
A13: Emergency Services Authorized Solely Under Prior Law | B13: ='C.1 Federal Expenditures'!$Q$12 -> 0 | D13: ='B. Total Expenditures'!$Q$12 -> 0 | E13: =D13/($D$44) -> 0
A14: Work, Education, and Training Activities | B14: ='C.1 Federal Expenditures'!$R$12 -> 28556476 | C14: ='C.2 State Expenditures'!$R$12 -> 1529222.2 | D14: ='B. Total Expenditures'!$R$12 -> 30085698 | E14: =D14/($D$44) -> 0.080921296
A15: Subsidized Employment | B15: ='C.1 Federal Expenditures'!$S$12 -> 0 | C15: ='C.2 State Expenditures'!$S$12 -> 0 | D15: ='B. Total Expenditures'!$S$12 -> 0 | E15: =D15/($D$44) -> 0
A16: Education and Training | B16: ='C.1 Federal Expenditures'!$T$12 -> 685017.94 | C16: ='C.2 State Expenditures'!$T$12 -> 0 | D16: ='B. Total Expenditures'!$T$12 -> 685017.94 | E16: =D16/($D$44) -> 0.0018424881
A17: Additional Work Activities | B17: ='C.1 Federal Expenditures'!$U$12 -> 27871458 | C17: ='C.2 State Expenditures'!$U$12 -> 1529222.2 | D17: ='B. Total Expenditures'!$U$12 -> 29400680 | E17: =D17/($D$44) -> 0.079078808
A18: Work Supports | B18: ='C.1 Federal Expenditures'!$V$12 -> 0 | C18: ='C.2 State Expenditures'!$V$12 -> 0 | D18: ='B. Total Expenditures'!$V$12 -> 0 | E18: =D18/($D$44) -> 0
A19: Early Care and Education | B19: ='C.1 Federal Expenditures'!$W$12 -> 14000000 | C19: ='C.2 State Expenditures'!$W$12 -> 32206079 | D19: ='B. Total Expenditures'!$W$12 -> 46206079 | E19: =D19/($D$44) -> 0.12428018
A20: Child Care (Assistance and Non-Assistance) | B20: ='C.1 Federal Expenditures'!$X$12 -> 14000000 | C20: ='C.2 State Expenditures'!$X$12 -> 32206079 | D20: ='B. Total Expenditures'!$X$12 -> 46206079 | E20: =D20/($D$44) -> 0.12428018
A21: Pre-Kindergarten/Head Start | B21: ='C.1 Federal Expenditures'!$Y$12 -> 0 | C21: ='C.2 State Expenditures'!$Y$12 -> 0 | D21: ='B. Total Expenditures'!$Y$12 -> 0 | E21: =D21/($D$44) -> 0
A22: Financial Education and Asset Development | B22: ='C.1 Federal Expenditures'!$Z$12 -> 0 | C22: ='C.2 State Expenditures'!$Z$12 -> 0 | D22: ='B. Total Expenditures'!$Z$12 -> 0 | E22: =D22/($D$44) -> 0
A23: Refundable Earned Income Tax Credits | B23: ='C.1 Federal Expenditures'!$AA$12 -> 0 | C23: ='C.2 State Expenditures'!$AA$12 -> 27922928 | D23: ='B. Total Expenditures'!$AA$12 -> 27922928 | E23: =D23/($D$44) -> 0.07510411
A24: Non-EITC Refundable State Tax Credits | B24: ='C.1 Federal Expenditures'!$AB$12 -> 0 | C24: ='C.2 State Expenditures'!$AB$12 -> 0 | D24: ='B. Total Expenditures'!$AB$12 -> 0 | E24: =D24/($D$44) -> 0
A25: Non-Recurrent Short Term Benefits | B25: ='C.1 Federal Expenditures'!$AC$12 -> 0 | C25: ='C.2 State Expenditures'!$AC$12 -> 1.8977046e+08 | D25: ='B. Total Expenditures'!$AC$12 -> 1.8977046e+08 | E25: =D25/($D$44) -> 0.51042432
A26: Supportive Services | B26: ='C.1 Federal Expenditures'!$AD$12 -> 900308.09 | C26: ='C.2 State Expenditures'!$AD$12 -> 201211.67 | D26: ='B. Total Expenditures'!$AD$12 -> 1101519.8 | E26: =D26/($D$44) -> 0.0029627502
A27: Services for Children and Youth | B27: ='C.1 Federal Expenditures'!$AE$12 -> 0 | C27: ='C.2 State Expenditures'!$AE$12 -> 0 | D27: ='B. Total Expenditures'!$AE$12 -> 0 | E27: =D27/($D$44) -> 0
A28: Prevention of Out-of-Wedlock Pregnancies | B28: ='C.1 Federal Expenditures'!$AF$12 -> 240975.34 | C28: ='C.2 State Expenditures'!$AF$12 -> 0 | D28: ='B. Total Expenditures'!$AF$12 -> 240975.34 | E28: =D28/($D$44) -> 0.00064814973
A29: Fatherhood and Two-Parent Family Formation and Maintenance Programs | B29: ='C.1 Federal Expenditures'!$AG$12 -> 0 | C29: ='C.2 State Expenditures'!$AG$12 -> 0 | D29: ='B. Total Expenditures'!$AG$12 -> 0 | E29: =D29/($D$44) -> 0
A30: Child Welfare Services | B30: ='C.1 Federal Expenditures'!$AH$12 -> 0 | C30: ='C.2 State Expenditures'!$AH$12 -> 0 | D30: ='B. Total Expenditures'!$AH$12 -> 0 | E30: =D30/($D$44) -> 0
A31: Family Support/Family Preservation /Reunification Services | B31: ='C.1 Federal Expenditures'!$AI$12 -> 0 | C31: ='C.2 State Expenditures'!$AI$12 -> 0 | D31: ='B. Total Expenditures'!$AI$12 -> 0 | E31: =D31/($D$44) -> 0
A32: Adoption Services | B32: ='C.1 Federal Expenditures'!$AJ$12 -> 0 | C32: ='C.2 State Expenditures'!$AJ$12 -> 0 | D32: ='B. Total Expenditures'!$AJ$12 -> 0 | E32: =D32/($D$44) -> 0
A33: Additional Child Welfare Services | B33: ='C.1 Federal Expenditures'!$AK$12 -> 0 | C33: ='C.2 State Expenditures'!$AK$12 -> 0 | D33: ='B. Total Expenditures'!$AK$12 -> 0 | E33: =D33/($D$44) -> 0
A34: Home Visiting Programs | B34: ='C.1 Federal Expenditures'!$AL$12 -> 0 | C34: ='C.2 State Expenditures'!$AL$12 -> 0 | D34: ='B. Total Expenditures'!$AL$12 -> 0 | E34: =D34/($D$44) -> 0
A35: Program Management | B35: ='C.1 Federal Expenditures'!$AM$12 -> 20618800 | C35: ='C.2 State Expenditures'!$AM$12 -> 0 | D35: ='B. Total Expenditures'!$AM$12 -> 20618800 | E35: =D35/($D$44) -> 0.055458246
A36: Administrative Costs | B36: ='C.1 Federal Expenditures'!$AN$12 -> 16367625 | C36: ='C.2 State Expenditures'!$AN$12 -> 0 | D36: ='B. Total Expenditures'!$AN$12 -> 16367625 | E36: =D36/($D$44) -> 0.044023891
A37: Assessment/Service Provision | B37: ='C.1 Federal Expenditures'!$AO$12 -> 3462138.6 | C37: ='C.2 State Expenditures'!$AO$12 -> 0 | D37: ='B. Total Expenditures'!$AO$12 -> 3462138.6 | E37: =D37/($D$44) -> 0.0093120905
A38: Systems | B38: ='C.1 Federal Expenditures'!$AP$12 -> 789035.92 | C38: ='C.2 State Expenditures'!$AP$12 -> 0 | D38: ='B. Total Expenditures'!$AP$12 -> 789035.92 | E38: =D38/($D$44) -> 0.0021222645
A39: Other | B39: ='C.1 Federal Expenditures'!$AQ$12 -> 0 | C39: ='C.2 State Expenditures'!$AQ$12 -> 0 | D39: ='B. Total Expenditures'!$AQ$12 -> 0 | E39: =D39/($D$44) -> 0
A40: TOTAL EXPENDITURES | B40: ='C.1 Federal Expenditures'!$AR$12 -> 1.0388737e+08 | C40: ='C.2 State Expenditures'!$AR$12 -> 2.6397932e+08 | D40: ='B. Total Expenditures'!$AR$12 -> 3.6786669e+08 | E40: =D40/($D$44) -> 0.98944853
...

Sheet F. Appendix
A1: F.: Appendix: Transitional Services for Employed and Job Access Expenditures in FY 2024
B2: Transitional Services for Employed | J2: Job Access
A3: STATE | B3: Total | C3: Federal | D3: State | E3: SFAG | F3: MOE in TANF | G3: MOE SSP | H3: Contingency | I3: STATE | J3: Total | K3: Federal | L3: State | M3: SFAG | N3: MOE in TANF | O3: MOE SSP | P3: Contingency
A4: U.S. TOTAL | B4: =C4+D4 -> 3.308603e+08 | C4: =E4+H4 -> 1.129521e+08 | D4: =G4+F4 -> 2.179082e+08 | E4: 1.129521e+08 | F4: 2.1450973e+08 | G4: 3398470 | H4: 0 | I4: U.S. TOTAL | J4: =K4+L4 -> 3345456.2 | K4: =M4+P4 -> 2100000 | L4: =O4+N4 -> 1245456.2 | M4: 2100000 | N4: 1245456.2 | O4: 0 | P4: 0
A5: ALABAMA | B5: =C5+D5 -> 0 | C5: =E5+H5 -> 0 | D5: =G5+F5 -> 0 | E5: 0 | F5: 0 | G5: 0 | H5: 0 | I5: ALABAMA | J5: =K5+L5 -> 0 | K5: =M5+P5 -> 0 | L5: =O5+N5 -> 0 | M5: 0 | N5: 0 | O5: 0 | P5: 0
A6: ALASKA | B6: =C6+D6 -> 0 | C6: =E6+H6 -> 0 | D6: =G6+F6 -> 0 | E6: 0 | F6: 0 | G6: 0 | H6: 0 | I6: ALASKA | J6: =K6+L6 -> 0 | K6: =M6+P6 -> 0 | L6: =O6+N6 -> 0 | M6: 0 | N6: 0 | O6: 0 | P6: 0
A7: ARIZONA | B7: =C7+D7 -> 0 | C7: =E7+H7 -> 0 | D7: =G7+F7 -> 0 | E7: 0 | F7: 0 | G7: 0 | H7: 0 | I7: ARIZONA | J7: =K7+L7 -> 0 | K7: =M7+P7 -> 0 | L7: =O7+N7 -> 0 | M7: 0 | N7: 0 | O7: 0 | P7: 0
A8: ARKANSAS | B8: =C8+D8 -> 0 | C8: =E8+H8 -> 0 | D8: =G8+F8 -> 0 | E8: 0 | F8: 0 | G8: 0 | H8: 0 | I8: ARKANSAS | J8: =K8+L8 -> 0 | K8: =M8+P8 -> 0 | L8: =O8+N8 -> 0 | M8: 0 | N8: 0 | O8: 0 | P8: 0
A9: CALIFORNIA | B9: =C9+D9 -> 3.0785421e+08 | C9: =E9+H9 -> 99042819 | D9: =G9+F9 -> 2.0881139e+08 | E9: 99042819 | F9: 2.0873764e+08 | G9: 73747.71 | H9: 0 | I9: CALIFORNIA | J9: =K9+L9 -> 0 | K9: =M9+P9 -> 0 | L9: =O9+N9 -> 0 | M9: 0 | N9: 0 | O9: 0 | P9: 0
A10: COLORADO | B10: =C10+D10 -> 3479314 | C10: =E10+H10 -> 3479314 | D10: =G10+F10 -> 0 | E10: 3479314 | F10: 0 | G10: 0 | H10: 0 | I10: COLORADO | J10: =K10+L10 -> 0 | K10: =M10+P10 -> 0 | L10: =O10+N10 -> 0 | M10: 0 | N10: 0 | O10: 0 | P10: 0
A11: CONNECTICUT | B11: =C11+D11 -> 3324722.3 | C11: =E11+H11 -> 0 | D11: =G11+F11 -> 3324722.3 | E11: 0 | F11: 0 | G11: 3324722.3 | H11: 0 | I11: CONNECTICUT | J11: =K11+L11 -> 0 | K11: =M11+P11 -> 0 | L11: =O11+N11 -> 0 | M11: 0 | N11: 0 | O11: 0 | P11: 0
A12: DELAWARE | B12: =C12+D12 -> 0 | C12: =E12+H12 -> 0 | D12: =G12+F12 -> 0 | E12: 0 | F12: 0 | G12: 0 | H12: 0 | I12: DELAWARE | J12: =K12+L12 -> 0 | K12: =M12+P12 -> 0 | L12: =O12+N12 -> 0 | M12: 0 | N12: 0 | O12: 0 | P12: 0
A13: DIST. OF COLUMBIA | B13: =C13+D13 -> 0 | C13: =E13+H13 -> 0 | D13: =G13+F13 -> 0 | E13: 0 | F13: 0 | G13: 0 | H13: 0 | I13: DIST. OF COLUMBIA | J13: =K13+L13 -> 0 | K13: =M13+P13 -> 0 | L13: =O13+N13 -> 0 | M13: 0 | N13: 0 | O13: 0 | P13: 0
A14: FLORIDA | B14: =C14+D14 -> 0 | C14: =E14+H14 -> 0 | D14: =G14+F14 -> 0 | E14: 0 | F14: 0 | G14: 0 | H14: 0 | I14: FLORIDA | J14: =K14+L14 -> 0 | K14: =M14+P14 -> 0 | L14: =O14+N14 -> 0 | M14: 0 | N14: 0 | O14: 0 | P14: 0
A15: GEORGIA | B15: =C15+D15 -> 0 | C15: =E15+H15 -> 0 | D15: =G15+F15 -> 0 | E15: 0 | F15: 0 | G15: 0 | H15: 0 | I15: GEORGIA | J15: =K15+L15 -> 0 | K15: =M15+P15 -> 0 | L15: =O15+N15 -> 0 | M15: 0 | N15: 0 | O15: 0 | P15: 0
... A55: WYOMING | B55: =C55+D55 -> 0 | C55: =E55+H55 -> 0 | D55: =G55+F55 -> 0 | E55: 0 | F55: 0 | G55: 0 | H55: 0 | I55: WYOMING | J55: =K55+L55 -> 0 | K55: =M55+P55 -> 0 | L55: =O55+N55 -> 0 | M55: 0 | N55: 0 | O55: 0 | P55: 0
A56: Updated 11.21.2025
A57: Transitional Services for Employed: Section 411(a)(5) of the Social Security Act requires states to report expenditures on transitional services for families who have ceased to receive assistance because of employment. This can include expenditures from a variety of individual categories, e.g., child care or supportive services; to avoid double-counting, these expenditures are reported as a separate line item apart from the other expenditure categories. Job Access: Expenditures of federal TANF block grant funds to meet the matching requirements for the Department of Transportation Job Access program. These expenditures are also included in “Work Supports.” To avoid double-counting, the Job Access expenditures are reported as a separate line item apart from the other expenditures categories. The amount of TANF funds expended on Job Access programs that may be used as non-federal matching under the Job Access program is limited to the difference between 30 percent of TANF block grant funds and the total amount transferred to SSBG and the Discretionary Fund of CCDF.
